2022-04-24 03:53:13,438 INFO    MainThread:9765 [internal.py:wandb_internal():93] W&B internal server running at pid: 9765, started at: 2022-04-24 03:53:13.438273
2022-04-24 03:53:15,589 DEBUG   SenderThread:9765 [sender.py:send():232] send: header
2022-04-24 03:53:15,589 INFO    WriterThread:9765 [datastore.py:open_for_write():75] open: /content/named_entity_recognition/wandb/run-20220424_035310-2739gzfb/run-2739gzfb.wandb
2022-04-24 03:53:15,724 DEBUG   SenderThread:9765 [sender.py:send():232] send: run
2022-04-24 03:53:15,831 ERROR   SenderThread:9765 [internal_api.py:execute():143] 404 response executing GraphQL.
2022-04-24 03:53:15,832 ERROR   SenderThread:9765 [internal_api.py:execute():144] {"errors":[{"message":"entity KOREAN_Tokenizing not found during upsertBucket","path":["upsertBucket"]}],"data":{"upsertBucket":null}}
2022-04-24 03:53:16,725 INFO    HandlerThread:9765 [handler.py:finish():806] shutting down handler
2022-04-24 03:53:16,728 INFO    WriterThread:9765 [datastore.py:close():279] close: /content/named_entity_recognition/wandb/run-20220424_035310-2739gzfb/run-2739gzfb.wandb
2022-04-24 03:53:16,729 ERROR   MainThread:9765 [internal.py:wandb_internal():165] Thread SenderThread:
Traceback (most recent call last):
  File "/usr/local/lib/python3.7/dist-packages/wandb/sdk/lib/retry.py", line 102, in __call__
    result = self._call_fn(*args, **kwargs)
  File "/usr/local/lib/python3.7/dist-packages/wandb/sdk/internal/internal_api.py", line 140, in execute
    return self.client.execute(*args, **kwargs)
  File "/usr/local/lib/python3.7/dist-packages/wandb/vendor/gql-0.2.0/wandb_gql/client.py", line 52, in execute
    result = self._get_result(document, *args, **kwargs)
  File "/usr/local/lib/python3.7/dist-packages/wandb/vendor/gql-0.2.0/wandb_gql/client.py", line 60, in _get_result
    return self.transport.execute(document, *args, **kwargs)
  File "/usr/local/lib/python3.7/dist-packages/wandb/vendor/gql-0.2.0/wandb_gql/transport/requests.py", line 39, in execute
    request.raise_for_status()
  File "/usr/local/lib/python3.7/dist-packages/requests/models.py", line 941, in raise_for_status
    raise HTTPError(http_error_msg, response=self)
requests.exceptions.HTTPError: 404 Client Error: Not Found for url: https://api.wandb.ai/graphql

During handling of the above exception, another exception occurred:

Traceback (most recent call last):
  File "/usr/local/lib/python3.7/dist-packages/wandb/apis/normalize.py", line 22, in wrapper
    return func(*args, **kwargs)
  File "/usr/local/lib/python3.7/dist-packages/wandb/sdk/internal/internal_api.py", line 1318, in upsert_run
    response = self.gql(mutation, variable_values=variable_values, **kwargs)
  File "/usr/local/lib/python3.7/dist-packages/wandb/sdk/lib/retry.py", line 118, in __call__
    if not check_retry_fn(e):
  File "/usr/local/lib/python3.7/dist-packages/wandb/util.py", line 879, in no_retry_auth
    raise CommError("Permission denied, ask the project owner to grant you access")
wandb.errors.CommError: Permission denied, ask the project owner to grant you access

During handling of the above exception, another exception occurred:

Traceback (most recent call last):
  File "/usr/local/lib/python3.7/dist-packages/wandb/sdk/internal/internal_util.py", line 51, in run
    self._run()
  File "/usr/local/lib/python3.7/dist-packages/wandb/sdk/internal/internal_util.py", line 102, in _run
    self._process(record)
  File "/usr/local/lib/python3.7/dist-packages/wandb/sdk/internal/internal.py", line 310, in _process
    self._sm.send(record)
  File "/usr/local/lib/python3.7/dist-packages/wandb/sdk/internal/sender.py", line 234, in send
    send_handler(record)
  File "/usr/local/lib/python3.7/dist-packages/wandb/sdk/internal/sender.py", line 692, in send_run
    self._init_run(run, config_value_dict)
  File "/usr/local/lib/python3.7/dist-packages/wandb/sdk/internal/sender.py", line 730, in _init_run
    commit=run.git.last_commit or None,
  File "/usr/local/lib/python3.7/dist-packages/wandb/apis/normalize.py", line 58, in wrapper
    raise CommError(message, err).with_traceback(sys.exc_info()[2])
  File "/usr/local/lib/python3.7/dist-packages/wandb/apis/normalize.py", line 22, in wrapper
    return func(*args, **kwargs)
  File "/usr/local/lib/python3.7/dist-packages/wandb/sdk/internal/internal_api.py", line 1318, in upsert_run
    response = self.gql(mutation, variable_values=variable_values, **kwargs)
  File "/usr/local/lib/python3.7/dist-packages/wandb/sdk/lib/retry.py", line 118, in __call__
    if not check_retry_fn(e):
  File "/usr/local/lib/python3.7/dist-packages/wandb/util.py", line 879, in no_retry_auth
    raise CommError("Permission denied, ask the project owner to grant you access")
wandb.errors.CommError: Permission denied, ask the project owner to grant you access
2022-04-24 03:53:18,762 INFO    MainThread:9765 [internal.py:handle_exit():80] Internal process exited
